2025-08-12 08:27:17,344 - ERROR - rexus.errors - ERROR
Message: Uncaught exception: OSError: [Errno 22] Invalid argument
File: C:\Users\itachi\Desktop\martin\Rexus.app\rexus\utils\error_handler.py:24
Function: handle_exception
---
Traceback (most recent call last):
  File "C:\Python310\lib\runpy.py", line 196, in _run_module_as_main
    return _run_code(code, main_globals, None,
  File "C:\Python310\lib\runpy.py", line 86, in _run_code
    exec(code, run_globals)
  File "C:\Users\itachi\AppData\Roaming\Python\Python310\site-packages\pytest\__main__.py", line 7, in <module>
    raise SystemExit(pytest.console_main())
  File "C:\Users\itachi\AppData\Roaming\Python\Python310\site-packages\_pytest\config\__init__.py", line 206, in console_main
    code = main()
  File "C:\Users\itachi\AppData\Roaming\Python\Python310\site-packages\_pytest\config\__init__.py", line 178, in main
    ret: Union[ExitCode, int] = config.hook.pytest_cmdline_main(
  File "C:\Users\itachi\AppData\Roaming\Python\Python310\site-packages\pluggy\_hooks.py", line 512, in __call__
    return self._hookexec(self.name, self._hookimpls.copy(), kwargs, firstresult)
  File "C:\Users\itachi\AppData\Roaming\Python\Python310\site-packages\pluggy\_manager.py", line 120, in _hookexec
    return self._inner_hookexec(hook_name, methods, kwargs, firstresult)
  File "C:\Users\itachi\AppData\Roaming\Python\Python310\site-packages\pluggy\_callers.py", line 167, in _multicall
    raise exception
  File "C:\Users\itachi\AppData\Roaming\Python\Python310\site-packages\pluggy\_callers.py", line 121, in _multicall
    res = hook_impl.function(*args)
  File "C:\Users\itachi\AppData\Roaming\Python\Python310\site-packages\_pytest\main.py", line 332, in pytest_cmdline_main
    return wrap_session(config, _main)
  File "C:\Users\itachi\AppData\Roaming\Python\Python310\site-packages\_pytest\main.py", line 320, in wrap_session
    config.hook.pytest_sessionfinish(
  File "C:\Users\itachi\AppData\Roaming\Python\Python310\site-packages\pluggy\_hooks.py", line 512, in __call__
    return self._hookexec(self.name, self._hookimpls.copy(), kwargs, firstresult)
  File "C:\Users\itachi\AppData\Roaming\Python\Python310\site-packages\pluggy\_manager.py", line 120, in _hookexec
    return self._inner_hookexec(hook_name, methods, kwargs, firstresult)
  File "C:\Users\itachi\AppData\Roaming\Python\Python310\site-packages\pluggy\_callers.py", line 167, in _multicall
    raise exception
  File "C:\Users\itachi\AppData\Roaming\Python\Python310\site-packages\pluggy\_callers.py", line 139, in _multicall
    teardown.throw(exception)
  File "C:\Users\itachi\AppData\Roaming\Python\Python310\site-packages\_pytest\logging.py", line 872, in pytest_sessionfinish
    return (yield)
  File "C:\Users\itachi\AppData\Roaming\Python\Python310\site-packages\pluggy\_callers.py", line 152, in _multicall
    teardown.send(result)
  File "C:\Users\itachi\AppData\Roaming\Python\Python310\site-packages\_pytest\terminal.py", line 877, in pytest_sessionfinish
    self.config.hook.pytest_terminal_summary(
  File "C:\Users\itachi\AppData\Roaming\Python\Python310\site-packages\pluggy\_hooks.py", line 512, in __call__
    return self._hookexec(self.name, self._hookimpls.copy(), kwargs, firstresult)
  File "C:\Users\itachi\AppData\Roaming\Python\Python310\site-packages\pluggy\_manager.py", line 120, in _hookexec
    return self._inner_hookexec(hook_name, methods, kwargs, firstresult)
  File "C:\Users\itachi\AppData\Roaming\Python\Python310\site-packages\pluggy\_callers.py", line 167, in _multicall
    raise exception
  File "C:\Users\itachi\AppData\Roaming\Python\Python310\site-packages\pluggy\_callers.py", line 116, in _multicall
    next(function_gen)  # first yield
  File "C:\Users\itachi\AppData\Roaming\Python\Python310\site-packages\_pytest\terminal.py", line 893, in pytest_terminal_summary
    self.summary_failures()
  File "C:\Users\itachi\AppData\Roaming\Python\Python310\site-packages\_pytest\terminal.py", line 1074, in summary_failures
    self.summary_failures_combined("failed", "FAILURES")
  File "C:\Users\itachi\AppData\Roaming\Python\Python310\site-packages\_pytest\terminal.py", line 1096, in summary_failures_combined
    self._outrep_summary(rep)
  File "C:\Users\itachi\AppData\Roaming\Python\Python310\site-packages\_pytest\terminal.py", line 1125, in _outrep_summary
    self._tw.line(content)
  File "C:\Users\itachi\AppData\Roaming\Python\Python310\site-packages\_pytest\_io\terminalwriter.py", line 173, in line
    self.write(s, **markup)
  File "C:\Users\itachi\AppData\Roaming\Python\Python310\site-packages\_pytest\_io\terminalwriter.py", line 158, in write
    self._file.write(msg)
OSError: [Errno 22] Invalid argument
